[0m16:48:21.578246 [debug] [MainThread]: Sending event: {'category': 'dbt', 'action': 'invocation', 'label': 'start', 'context': [<snowplow_tracker.self_describing_json.SelfDescribingJson object at 0x104397560>, <snowplow_tracker.self_describing_json.SelfDescribingJson object at 0x104a22750>, <snowplow_tracker.self_describing_json.SelfDescribingJson object at 0x104a224b0>]}


============================== 16:48:21.580584 | 41cfbfab-4c07-4bd1-a2ef-966c231b91b1 ==============================
[0m16:48:21.580584 [info ] [MainThread]: Running with dbt=1.10.7
[0m16:48:21.580856 [debug] [MainThread]: running dbt with arguments {'printer_width': '80', 'indirect_selection': 'eager', 'write_json': 'True', 'log_cache_events': 'False', 'partial_parse': 'True', 'cache_selected_only': 'False', 'profiles_dir': '/Users/rajanya/.dbt', 'debug': 'False', 'version_check': 'True', 'log_path': 'logs', 'warn_error': 'None', 'fail_fast': 'False', 'use_colors': 'True', 'use_experimental_parser': 'False', 'empty': 'None', 'quiet': 'False', 'no_print': 'None', 'log_format': 'default', 'static_parser': 'True', 'introspect': 'True', 'invocation_command': 'dbt docs serve --port 8081', 'target_path': 'None', 'warn_error_options': 'WarnErrorOptionsV2(error=[], warn=[], silence=[])', 'send_anonymous_usage_stats': 'True'}
[0m16:48:21.581117 [error] [MainThread]: Encountered an error:
Runtime Error
  No dbt_project.yml found at expected path /Users/rajanya/Documents/Ohio_newTransit/dbt_project.yml
  Verify that each entry within packages.yml (and their transitive dependencies) contains a file named dbt_project.yml
  
[0m16:48:21.582898 [debug] [MainThread]: Resource report: {"command_name": "serve", "command_success": false, "command_wall_clock_time": 0.041300416, "process_in_blocks": "0", "process_kernel_time": 0.130146, "process_mem_max_rss": "108937216", "process_out_blocks": "0", "process_user_time": 0.590622}
[0m16:48:21.583166 [debug] [MainThread]: Command `dbt docs serve` failed at 16:48:21.583128 after 0.04 seconds
[0m16:48:21.583298 [debug] [MainThread]: Sending event: {'category': 'dbt', 'action': 'invocation', 'label': 'end', 'context': [<snowplow_tracker.self_describing_json.SelfDescribingJson object at 0x104424800>, <snowplow_tracker.self_describing_json.SelfDescribingJson object at 0x1046ddac0>, <snowplow_tracker.self_describing_json.SelfDescribingJson object at 0x104394680>]}
[0m16:48:21.583425 [debug] [MainThread]: Flushing usage events
[0m16:48:21.895380 [debug] [MainThread]: An error was encountered while trying to flush usage events
